2025-09-10 03:26:28,740 - ERROR - Migration failed: DATABASE_URL must be provided via environment or parameter
2025-09-10 03:26:34,494 - INFO - Checking database connection...
2025-09-10 03:26:34,494 - INFO - Running: alembic current
2025-09-10 03:26:37,533 - ERROR - Command failed: Command '['alembic', 'current']' returned non-zero exit status 1.
2025-09-10 03:26:37,533 - ERROR - Error: Traceback (most recent call last):
  File "/usr/local/bin/alembic", line 7, in <module>
    sys.exit(main())
             ~~~~^^
  File "/usr/local/lib/python3.13/site-packages/alembic/config.py", line 636, in main
    CommandLine(prog=prog).main(argv=argv)
    ~~~~~~~~~~~~~~~~~~~~~~~~~~~^^^^^^^^^^^
  File "/usr/local/lib/python3.13/site-packages/alembic/config.py", line 626, in main
    self.run_cmd(cfg, options)
    ~~~~~~~~~~~~^^^^^^^^^^^^^^
  File "/usr/local/lib/python3.13/site-packages/alembic/config.py", line 603, in run_cmd
    fn(
    ~~^
        config,
        ^^^^^^^
        *[getattr(options, k, None) for k in positional],
        ^^^^^^^^^^^^^^^^^^^^^^^^^^^^^^^^^^^^^^^^^^^^^^^^^
        **{k: getattr(options, k, None) for k in kwarg},
        ^^^^^^^^^^^^^^^^^^^^^^^^^^^^^^^^^^^^^^^^^^^^^^^^
    )
    ^
  File "/usr/local/lib/python3.13/site-packages/alembic/command.py", line 632, in current
    script.run_env()
    ~~~~~~~~~~~~~~^^
  File "/usr/local/lib/python3.13/site-packages/alembic/script/base.py", line 586, in run_env
    util.load_python_file(self.dir, "env.py")
    ~~~~~~~~~~~~~~~~~~~~~^^^^^^^^^^^^^^^^^^^^
  File "/usr/local/lib/python3.13/site-packages/alembic/util/pyfiles.py", line 95, in load_python_file
    module = load_module_py(module_id, path)
  File "/usr/local/lib/python3.13/site-packages/alembic/util/pyfiles.py", line 113, in load_module_py
    spec.loader.exec_module(module)  # type: ignore
    ~~~~~~~~~~~~~~~~~~~~~~~^^^^^^^^
  File "<frozen importlib._bootstrap_external>", line 1026, in exec_module
  File "<frozen importlib._bootstrap>", line 488, in _call_with_frames_removed
  File "/Users/stephanerichard/Documents/CODING/ReactDjango-Hub/services/identity-service/alembic/env.py", line 91, in <module>
    run_migrations_online()
    ~~~~~~~~~~~~~~~~~~~~~^^
  File "/Users/stephanerichard/Documents/CODING/ReactDjango-Hub/services/identity-service/alembic/env.py", line 73, in run_migrations_online
    connectable = engine_from_config(
        configuration,
        prefix="sqlalchemy.",
        poolclass=pool.NullPool,
    )
  File "/usr/local/lib/python3.13/site-packages/sqlalchemy/engine/create.py", line 838, in engine_from_config
    return create_engine(url, **options)
  File "<string>", line 2, in create_engine
  File "/usr/local/lib/python3.13/site-packages/sqlalchemy/util/deprecations.py", line 281, in warned
    return fn(*args, **kwargs)  # type: ignore[no-any-return]
  File "/usr/local/lib/python3.13/site-packages/sqlalchemy/engine/create.py", line 617, in create_engine
    dbapi = dbapi_meth(**dbapi_args)
  File "/usr/local/lib/python3.13/site-packages/sqlalchemy/dialects/postgresql/psycopg2.py", line 696, in import_dbapi
    import psycopg2
ModuleNotFoundError: No module named 'psycopg2'

